<mujoco model="lbr_iiwa">
    <compiler angle="radian" />
    <size njmax="500" nconmax="100" />
    <actuator>
        <motor ctrllimited="true" ctrlrange="-176.0 176.0" joint="lbr_iiwa_joint_1" name="torq_j1"/>
        <motor ctrllimited="true" ctrlrange="-176.0 176.0" joint="lbr_iiwa_joint_2" name="torq_j2"/>
        <motor ctrllimited="true" ctrlrange="-110.0 110.0" joint="lbr_iiwa_joint_3" name="torq_j3"/>
        <motor ctrllimited="true" ctrlrange="-110.0 110.0" joint="lbr_iiwa_joint_4" name="torq_j4"/>
        <motor ctrllimited="true" ctrlrange="-110.0 110.0" joint="lbr_iiwa_joint_5" name="torq_j5"/>
        <motor ctrllimited="true" ctrlrange="-40.0 40.0" joint="lbr_iiwa_joint_6" name="torq_j6"/>
        <motor ctrllimited="true" ctrlrange="-40.0 40.0" joint="lbr_iiwa_joint_7" name="torq_j7"/>
    </actuator>
    <asset>
        <mesh name="link_0" file="meshes/link_0.stl" />
        <mesh name="link_1" file="meshes/link_1.stl" />
        <mesh name="link_2" file="meshes/link_2.stl" />
        <mesh name="link_3" file="meshes/link_3.stl" />
        <mesh name="link_4" file="meshes/link_4.stl" />
        <mesh name="link_5" file="meshes/link_5.stl" />
        <mesh name="link_6" file="meshes/link_6.stl" />
        <mesh name="link_7" file="meshes/link_7.stl" />
        <texture type="skybox" builtin="gradient" width="128" height="128" rgb1=".4 .6 .8" 
            rgb2="0 0 0"/>  
        <texture name="texgeom" type="cube" builtin="flat" mark="cross" width="127" height="1278" 
            rgb1="0.8 0.6 0.4" rgb2="0.8 0.6 0.4" markrgb="1 1 1" random="0.01"/>  
        <texture name="texplane" type="2d" builtin="checker" rgb1=".2 .3 .4" rgb2=".1 0.15 0.2" 
            width="512" height="512"/> 
        <material name='MatPlane' reflectance='0.5' texture="texplane" texrepeat="1 1" texuniform="true"/>
        <material name='geom' texture="texgeom" texuniform="true"/>
    </asset>
    
    <worldbody>
        <light directional='false' diffuse='.8 .8 .8' specular='0.3 0.3 0.3' pos='0 0 4.0' dir='0 -.15 -1'/>
        <geom name='floor' pos='0 -1 0' size='1.5 3 .125' type='plane' material="MatPlane" condim='3'/>

        <geom type="mesh" rgba="0.2 0.2 0.2 1" mesh="link_0" />
        <body name="lbr_iiwa_link_1" pos="0 0 0.1575">
            <inertial pos="0 -0.03 0.12" mass="4" diaginertia="0.1 0.09 0.02" />
            <joint name="lbr_iiwa_joint_1" type="hinge" pos="0 0 0" axis="0 0 1" limited="true" range="-1.96706 1.96706" damping="0.5" />
            <geom type="mesh" rgba="0.5 0.7 1 1" mesh="link_1" />
            <body name="lbr_iiwa_link_2" pos="0 0 0.2025" quat="0 0 0.707107 0.707107">
                <inertial pos="0.0003 0.059 0.042" quat="0.707107 0.707107 0 0" mass="4" diaginertia="0.05 0.044 0.018" />
                <joint name="lbr_iiwa_joint_2" type="hinge" pos="0 0 0" axis="0 0 1" limited="true" range="-2.0944 2.0944" damping="0.5" />
                <geom type="mesh" rgba="0.5 0.7 1 1" mesh="link_2" />
                <body name="lbr_iiwa_link_3" pos="0 0.2045 0" quat="0 0 0.707107 0.707107">
                    <inertial pos="0 0.03 0.13" mass="3" diaginertia="0.08 0.075 0.01" />
                    <joint name="lbr_iiwa_joint_3" type="hinge" pos="0 0 0" axis="0 0 1" limited="true" range="-2.96706 2.96706" damping="0.5" />
                    <geom type="mesh" rgba="1 0.423529 0.0392157 1" mesh="link_3" />
                    <body name="lbr_iiwa_link_4" pos="0 0 0.2155" quat="0.707107 0.707107 0 0">
                        <inertial pos="0 0.067 0.034" quat="0.707107 0.707107 0 0" mass="2.7" diaginertia="0.03 0.029 0.01" />
                        <joint name="lbr_iiwa_joint_4" type="hinge" pos="0 0 0" axis="0 0 1" limited="true" range="-2.2944 2.2944" damping="0.5" />
                        <geom type="mesh" rgba="0.5 0.7 1 1" mesh="link_4" />
                        <body name="lbr_iiwa_link_5" pos="0 0.1845 0" quat="0 0 0.707107 0.707107">
                            <inertial pos="0.0001 0.021 0.076" mass="1.7" diaginertia="0.02 0.018 0.005" />
                            <joint name="lbr_iiwa_joint_5" type="hinge" pos="0 0 0" axis="0 0 1" limited="true" range="-2.96706 2.96706" damping="0.5" />
                            <geom type="mesh" rgba="0.5 0.7 1 1" mesh="link_5" />
                            <body name="lbr_iiwa_link_6" pos="0 0 0.2155" quat="0.707107 0.707107 0 0">
                                <inertial pos="0 0.0006 0.0004" quat="0.707107 0.707107 0 0" mass="1.8" diaginertia="0.005 0.0047 0.0036" />
                                <joint name="lbr_iiwa_joint_6" type="hinge" pos="0 0 0" axis="0 0 1" limited="true" range="-2.0944 2.0944" damping="0.5" />
                                <geom type="mesh" rgba="1 0.423529 0.0392157 1" mesh="link_6" />
                                <body name="lbr_iiwa_link_7" pos="0 0.081 0" quat="0 0 0.707107 0.707107">
                                    <inertial pos="0.01125 0 0.03625" quat="0.954514 0 0.298168 0" mass="0.4" diaginertia="1.00147 1.00147 1.001" />
                                    <joint name="lbr_iiwa_joint_7" type="hinge" pos="0 0 0" axis="0 0 1" limited="true" range="-3.05433 3.05433" damping="0.5" />
                                    <geom type="mesh" rgba="0.2 0.2 0.2 1" mesh="link_7" />

        <!-- rope and ball -->
        <body name="cap0" pos="0.025 0 0.04">
            <joint name="joint_iiwa_rope0" type="hinge" axis="0 1 0" pos="0 0 0.015" damping="0" stiffness="0"/>
            <joint name="joint_iiwa_rope1" type="hinge" axis="1 0 0" pos="0 0 0.015" damping="0" stiffness="0"/>
            <geom type="capsule" size=".005 .01" rgba=".8 .2 .1 1" mass="0.001"/>
            <body name="cap1" pos="0 0 -0.03">
                <joint name="joint01_0" type="hinge" axis="0 1 0" pos="0 0 0.015" damping="0" stiffness="0"/>
                <joint name="joint01_1" type="hinge" axis="1 0 0" pos="0 0 0.015" damping="0" stiffness="0"/>
                <geom type="capsule" size=".005 .01" rgba=".8 .2 .1 1" mass="0.001"/>
                <body name="cap2" pos="0 0 -0.03">
                    <!--<inertial pos="0 0 0" quat="0 0 0 1" mass="0.01" diaginertia="0.003 0.002 0.002" />-->
                    <joint name="joint12_0" type="hinge" axis="0 1 0" pos="0 0 0.015" damping="0" stiffness="0"/>
                    <joint name="joint12_1" type="hinge" axis="1 0 0" pos="0 0 0.015" damping="0" stiffness="0"/>
                    <geom type="capsule" size=".005 .01" rgba=".8 .2 .1 1" mass="0.001"/>
                    <body name="cap3" pos="0 0 -0.03">
                        <joint name="joint23_0" type="hinge" axis="0 1 0" pos="0 0 0.015" damping="0" stiffness="0"/>
                        <joint name="joint23_1" type="hinge" axis="1 0 0" pos="0 0 0.015" damping="0" stiffness="0"/>
                        <geom type="capsule" size=".005 .01" rgba=".8 .2 .1 1" mass="0.001"/>
                        <body name="cap4" pos="0 0 -0.03">
                            <joint name="joint34_0" type="hinge" axis="0 1 0" pos="0 0 0.015" damping="0" stiffness="0"/>
                            <joint name="joint34_1" type="hinge" axis="1 0 0" pos="0 0 0.015" damping="0" stiffness="0"/>
                            <geom type="capsule" size=".005 .01" rgba=".8 .2 .1 1" mass="0.001"/>
                            <body name="cap5" pos="0 0 -0.03">
                                <joint name="joint45_0" type="hinge" axis="0 1 0" pos="0 0 0.015" damping="0" stiffness="0"/>
                                <joint name="joint45_1" type="hinge" axis="1 0 0" pos="0 0 0.015" damping="0" stiffness="0"/>
                                <geom type="capsule" size=".005 .01" rgba=".8 .2 .1 1" mass="0.001"/>
                                <body name="cap6" pos="0 0 -0.03">
                                    <joint name="joint56_0" type="hinge" axis="0 1 0" pos="0 0 0.015" damping="0" stiffness="0"/>
                                    <joint name="joint56_1" type="hinge" axis="1 0 0" pos="0 0 0.015" damping="0" stiffness="0"/>
                                    <geom type="capsule" size=".005 .01" rgba=".8 .2 .1 1" mass="0.001"/>
                                    <body name="cap7" pos="0 0 -0.03">
                                        <joint name="joint67_0" type="hinge" axis="0 1 0" pos="0 0 0.015" damping="0" stiffness="0"/>
                                        <joint name="joint67_1" type="hinge" axis="1 0 0" pos="0 0 0.015" damping="0" stiffness="0"/>
                                        <geom type="capsule" size=".005 .01" rgba=".8 .2 .1 1" mass="0.001"/>
                                        <body name="cap8" pos="0 0 -0.03">
                                            <joint name="joint78_0" type="hinge" axis="0 1 0" pos="0 0 0.015" damping="0" stiffness="0"/>
                                            <joint name="joint78_1" type="hinge" axis="1 0 0" pos="0 0 0.015" damping="0" stiffness="0"/>
                                            <geom type="capsule" size=".005 .01" rgba=".8 .2 .1 1" mass="0.001"/>
                                            <body name="cap9" pos="0 0 -0.03">
                                                <joint name="joint89_0" type="hinge" axis="0 1 0" pos="0 0 0.015" damping="0" stiffness="0"/>
                                                <joint name="joint89_1" type="hinge" axis="1 0 0" pos="0 0 0.015" damping="0" stiffness="0"/>
                                                <geom type="capsule" size=".005 .01" rgba=".8 .2 .1 1" mass="0.001"/>
                                                <body name="cap10" pos="0 0 -0.03">
                                                    <joint name="joint910_0" type="hinge" axis="0 1 0" pos="0 0 0.015" damping="0" stiffness="0"/>
                                                    <joint name="joint910_1" type="hinge" axis="1 0 0" pos="0 0 0.015" damping="0" stiffness="0"/>
                                                    <geom type="capsule" size=".005 .01" rgba=".8 .2 .1 1" mass="0.001"/>
                                                    <body name="ball" pos="0 0 -0.04">
                                                        <geom name="ball" type="sphere" size=".02"  rgba=".7 .4 .2 1" mass="0.02"/>
                                                    </body>
                                                </body>
                                            </body>
                                        </body>
                                    </body>
                                </body>
                            </body>
                        </body>
                    </body>
                </body>
            </body>
        </body> 
                                </body>
                            </body>
                        </body>
                    </body>
                </body>
            </body>
        </body>
    </worldbody>
</mujoco>
